<?xml version="1.0"?>
<robot name="puzzlebot">

  <material name="chassis_color">
    <color rgba="0.2 0.5 0.1 0.8"/>
  </material>
  
  <material name="puzzlebot_color">
    <color rgba="0.8 0.8 0.8 0.5"/>
  </material>
  
  <material name="wheel_color">
    <color rgba="0.1 0.1 0.1 1.0"/>
  </material>

  <!-- Chassis Link -->
  <link name="base_link">
    <visual>
      <origin rpy="1.57 0 0" xyz="0 0 0.05"  /> <!-- 90 degrees rotation around the X-axis -->
      <geometry>
        <mesh filename="package://urdf_tutorial_r2d2/meshes/MCR2_1000_13_Chassis.stl"/>
      </geometry>
      <material name="chassis_color"/>
    </visual>
  </link>

  <!-- Puzzlebot Part (Assumed as a cover or secondary chassis) -->
  <link name="puzzlebot_part">
    <visual>
      <origin rpy="0 0 -1.57" xyz="0 0 0"  />
      <geometry>
        <mesh filename="package://urdf_tutorial_r2d2/meshes/MCR2_1000_0_Puzzlebot.stl"/>
      </geometry>
      <material name="puzzlebot_color"/>
    </visual>
  </link>


  <!--L Wheel Link -->
  <link name="wheel_right">
    <visual>
      <origin rpy="1.57 0 1.57" xyz="0 0 0"  /> <!-- 90 degrees rotation around the X-axis -->
      <geometry>
        <mesh filename="package://urdf_tutorial_r2d2/meshes/MCR2_1000_1_1_Wheel_Coupler_2.stl"/>
      </geometry>
      <material name="wheel_color"/>
    </visual>
  </link>
  
  <!--R Wheel Link -->
  <link name="wheel_left">
    <visual>
      <origin rpy="1.57 0 1.57" xyz="0 0 0"  /> <!-- 90 degrees rotation around the X-axis -->
      <geometry>
        <mesh filename="package://urdf_tutorial_r2d2/meshes/MCR2_1000_1_1_Wheel_Coupler_2.stl"/>
      </geometry>
      <material name="wheel_color"/>
    </visual>
  </link>

  <!-- Joint between chassis and puzzlebot_part -->
  <joint name="puzzlebot_joint" type="fixed">
    <parent link="base_link"/>
    <child link="puzzlebot_part"/>
    <origin xyz="0 0 0.05" rpy="0 0 0"/> <!-- Adjust the offset as necessary -->
  </joint>

  <!-- Joint between chassis and wheel -->
  <joint name="r_wheel_joint" type="continuous">
    <parent link="base_link"/>
    <child link="wheel_right"/>
    <axis xyz="1 0 0"/> <!-- Rotation axis -->
    <origin xyz="0.1 -0.05 0.05" rpy="0 0 0"/> <!-- Rotated the wheel by 90 degrees (1.5708 radians) around the Y-axis -->

  </joint>
  
  <!-- Joint between chassis and wheel -->
  <joint name="l_wheel_joint" type="continuous">
    <parent link="base_link"/>
    <child link="wheel_left"/>
    <axis xyz="1 0 0"/> <!-- Rotation axis -->
    <origin xyz="-0.105 -0.05 0.05" rpy="0 0 0"/> <!-- Rotated the wheel by 90 degrees (1.5708 radians) around the Y-axis -->
  </joint>

</robot>

